<?xml version="1.0" encoding="utf-8"?>

<mujoco model="dual ur3 larr (right arm)">

    <body name="right_base_link" pos="0 0 0" quat="0 0 0 1">
        <inertial pos="0 0 0" quat="0.5 0.5 -0.5 0.5" mass="2" diaginertia="0.005625 0.00305317 0.00305317" />
        <geom type="mesh" mesh="ur_base" material="RobMat" pos="0 0 -0.00001" /> <!--Need gap to prevent collision-->
        <body name="right_shoulder_link" pos="0 0 0.1519">
            <inertial pos="0 0 0" mass="2" diaginertia="0.00809316 0.00809316 0.005625" />
            <joint name="right_shoulder_pan_joint" pos="0 0 0" axis="0 0 1" limited="true" range="-6.28319 6.28319" damping="10" />
            <geom type="mesh" mesh="shoulder" material="RobMat" />
            <body name="right_upper_arm_link" pos="0 0.1198 0" quat="0.707107 0 0.707107 0">
                <inertial pos="0 0 0.121825" mass="3.42" diaginertia="0.0217285 0.0217285 0.00961875" />
                <joint name="right_shoulder_lift_joint" pos="0 0 0" axis="0 1 0" limited="true" range="-6.28319 6.28319" damping="10" />
                <geom type="mesh" mesh="upperarm" material="RobMat" />
                <body name="right_forearm_link" pos="0 -0.0925 0.24365">
                    <inertial pos="0 0 0.106625" mass="1.26" diaginertia="0.00654681 0.00654681 0.00354375" />
                    <joint name="right_elbow_joint" pos="0 0 0" axis="0 1 0" limited="true" range="-3.14159 3.14159" damping="10" />
                    <geom type="mesh" mesh="forearm" material="RobMat"/>
                    <body name="right_wrist_1_link" pos="0 0 0.21325" quat="0.707107 0 0.707107 0">
                        <inertial pos="0 0 0" quat="0.5 0.5 -0.5 0.5" mass="0.8" diaginertia="0.00225 0.002085 0.002085" />
                        <joint name="right_wrist_1_joint" pos="0 0 0" axis="0 1 0" limited="true" range="-6.28319 6.28319" damping="10" />
                        <geom type="mesh" mesh="wrist1" material="RobMat"/>
                        <body name="right_wrist_2_link" pos="0 0.08105 0">
                            <inertial pos="0 0 0" quat="0.5 0.5 -0.5 0.5" mass="0.8" diaginertia="0.00225 0.002085 0.002085" />
                            <joint name="right_wrist_2_joint" pos="0 0 0" axis="0 0 1" limited="true" range="-6.28319 6.28319" damping="10" />
                            <geom type="mesh" mesh="wrist2" material="RobMat" />
                            <body name="right_wrist_3_link" pos="0 0 0.08535">
                                <inertial pos="0 0 0" quat="0.5 0.5 -0.5 0.5" mass="0.35" diaginertia="0.000984375 0.000912187 0.000912187" />
                                <joint name="right_wrist_3_joint" pos="0 0 0" axis="0 1 0" limited="true" range="-6.28319 6.28319" damping="10" />
                                <geom type="mesh" mesh="wrist3" material="RobMat"/>

                                <body name="right_ee_link" pos="0 0.0819 0" quat="0.707 -0.707 0 0" >
                                    <!--Import Robotiq 2F-85 Gripper-->
                                    <include file="dual_ur3_larr_right_hand.xml"/> 
                                </body>

                            </body>
                        </body>
                    </body>
                </body>
            </body>
        </body>
    </body>

</mujoco>